Workbook
Name nADM_A_Date: Administrations!$O$5:$O$83
Name nADM_A_Dated: Administrations!$AP$5:$AP$83
Name nADM_A_Err: Administrations!$W$5:$W$83
Name nADM_A_Hi: Administrations!$AA$5:$AA$83
Name nADM_A_HT: Administrations!$X$5:$X$83
Name nADM_A_Lo: Administrations!$Z$5:$Z$83
Name nADM_A_Loc: Administrations!$AB$5:$AB$83
Name nADM_A_Lower: Administrations!$T$5:$T$83
Name nADM_A_Month: Administrations!$S$5:$S$83
Name nADM_A_Off: Administrations!$Q$5:$Q$83
Name nADM_A_OK: Administrations!$Y$5:$Y$83
Name nADM_A_Prec: Administrations!$N$5:$N$83
Name nADM_A_Src: Administrations!$V$5:$V$83
Name nADM_A_Text: Administrations!$M$5:$M$83
Name nADM_A_Time: Administrations!$P$5:$P$83
Name nADM_A_Upper: Administrations!$U$5:$U$83
Name nADM_A_UTC: Administrations!$AC$5:$AC$83
Name nADM_A_Year: Administrations!$R$5:$R$83
Name nADM_Admin_ID: Administrations!$C$5:$C$83
Name nADM_BSA_key: Administrations!$AZ$5:$AZ$83
Name nADM_BSA_m2: Administrations!$J$5:$J$83
Name nADM_BSA_missing: Administrations!$BB$5:$BB$83
Name nADM_BSA_n: Administrations!$AY$5:$AY$83
Name nADM_Case_ID: Administrations!$A$5:$A$83
Name nADM_Case_Version: Administrations!$B$5:$B$83
Name nADM_Check_Message: Administrations!$BT$5:$BT$83
Name nADM_Dose: Administrations!$F$5:$F$83
Name nADM_Dose_n: Administrations!$AV$5:$AV$83
Name nADM_Dose_per_BSA: Administrations!$BD$5:$BD$83
Name nADM_Dose_pos_n: Administrations!$AW$5:$AW$83
Name nADM_Dose_Unit: Administrations!$G$5:$G$83
Name nADM_Dup: Administrations!$AM$5:$AM$83
Name nADM_End_Date: Administrations!$AD$5:$AD$83
Name nADM_End_Off: Administrations!$AF$5:$AF$83
Name nADM_End_Src: Administrations!$AG$5:$AG$83
Name nADM_End_Time: Administrations!$AE$5:$AE$83
Name nADM_Ep_Found: Administrations!$BR$5:$BR$83
Name nADM_Exposure_Episode_ID: Administrations!$D$5:$D$83
Name nADM_HasBSA: Administrations!$BA$5:$BA$83
Name nADM_HasDose: Administrations!$AX$5:$AX$83
Name nADM_Key: Administrations!$AL$5:$AL$83
Name nADM_Kind: Administrations!$E$5:$E$83
Name nADM_Known: Administrations!$BC$5:$BC$83
Name nADM_Lo_n: Administrations!$AS$5:$AS$83
Name nADM_Loc_n: Administrations!$AQ$5:$AQ$83
Name nADM_Missing_Reason: Administrations!$K$5:$K$83
Name nADM_Notes: Administrations!$L$5:$L$83
Name nADM_Ovl_Loc: Administrations!$BO$5:$BO$83
Name nADM_Ovl_UTC: Administrations!$BP$5:$BP$83
Name nADM_Q10_DateErr: Administrations!$BF$5:$BF$83
Name nADM_Q10_Raw: Administrations!$BE$5:$BE$83
Name nADM_Rate: Administrations!$H$5:$H$83
Name nADM_Rate_n: Administrations!$AU$5:$AU$83
Name nADM_Rate_Unit: Administrations!$I$5:$I$83
Name nADM_Record_Check: Administrations!$BS$5:$BS$83
Name nADM_Rev_Loc: Administrations!$BM$5:$BM$83
Name nADM_Rev_UTC: Administrations!$BN$5:$BN$83
Name nADM_RowN: Administrations!$AT$5:$AT$83
Name nADM_SE_Err: Administrations!$AH$5:$AH$83
Name nADM_SE_Loc: Administrations!$AI$5:$AI$83

Sheet Read_Me
B1: Time to Onset in Drug Safety: companion Excel workbook
B2: TTO Companion Tools v1.1 (CALC-SPEC 1.1)
B3: Companion to "Time to Onset in Drug Safety: A Technical Guide to ICSR Analysis Using Mechanism of Action, Pharmacokinetics and Pharmacodynamics" by Dr. Hafez Selim (Chapter 23, Use the Excel worksheets).
B5: Educational tool: read before use
B6: This workbook is an educational tool for training, self-study and careful desk work on individual case safety reports (ICSRs). It is NOT validated for regulated production use. It is NOT a dosing calculator and gives no dosing recommendation. It NEVER assigns causality and never produces a causality category, a probability or a statement that an event is related to a drug. Every result describes timing or exposure under the assumptions shown beside it; the formal causality assessment remains a human judgment.
B7: Sheet protection only prevents accidental edits; it is not a security control. The workbook contains no macros, no VBA, no external links and no network connections, so case data stay on your computer. Use fictional or de-identified data for training.
B9: Version | C9: TTO Companion Tools v1.1 (CALC-SPEC 1.1). Calculation rules: CALC-SPEC 1.1 (Stage 1 document C), the same rules as the interactive calculator version 1.1. Verification vectors: tto_calc_test_vectors_v1.1.json (V01-V38; 36 numeric).
B10: License | C10: Creative Commons Attribution-NonCommercial 4.0 International (CC BY-NC 4.0), https://creativecommons.org/licenses/by-nc/4.0/
B11: Source and updates | C11: https://github.com/abdu94-hash/tto-companion-tools (the interactive calculator built on the same CALC-SPEC is at https://abdu94-hash.github.io/tto-companion-tools/)
B12: Verification status | C12: =nVER_Overall -> PASS: all 36 numeric vectors reproduce within the JSON tolerance
B13: Examples status | C13: =nEX_Status -> MATCH: all 90 example checks reproduce the home chapters' numbers
B14: Tested environment | C14: Built and verified with Microsoft Excel for Windows, version 16.0 (build 20527), on 25 October 2026, and checked with verify_workbook.ps1 (the Verification and Examples status lines above are recalculated by the workbook itself). Formulas use only functions available in Excel 2010 and later (AGGREGATE, SUMPRODUCT, COUNTIFS; no LET, LAMBDA, dynamic arrays or TEXTJOIN). Not yet verified in Excel for the web, Excel for Mac, Google Sheets or LibreOffice. Some text formats (TEXT with yyyy-mm-dd on the Export sheet) assume English format codes.
B15: Changes in version 1.1 | C15: All 14 agreed rules of CALC-SPEC 1.1: every E-code listed (G9); the laboratory-defined onset (precision LAB); C5 by UTC instant with partial-date and tie blocking; C7 counting recorded interventions only, ends included; the complete common gate; Q6 named uses; Q8 antibody caution; Q10 Method B by date; units; display in powers of ten below 0.0001%; the finest rule by default; the C-rule limitations text; the Summary and Export sheets; vectors V28-V38.
B17: How to use (the workup of Chapter 23)
B18: 1. Cases | C18: Open a case version (Case_ID + Case_Version). Follow-up adds a new version; earlier rows stay (V12).
B19: 2. Record the sources | C19: On Exposures, Administrations, Events and Milestones enter every date, time and timing statement as the source gives it: original text, precision, bounds and source. Never type 0, N/A or a typical value to make a row calculate. A laboratory-defined onset (CALC-SPEC 1.1 C4) is precision LAB on Events with the Milestone_IDs of the last normal test and the first abnormal test; no other date is used in their place.
B20: 3. Drug_Event_Links | C20: Create the drug-event pairs you intend to compare, each with a reason. An interval without a link shows E_MISSING_LINK.
B21: 4. Intervals | C21: One row per link and anchor. Leave the rule blank to use the finest rule both records support (C1 two timestamps, C2 two exact dates, C4 bounds), or choose a coarser one; a finer one is blocked (E_MISSING_INPUT). Leave the end point blank for the onset of the linked event. LAST_DOSE_BEFORE_ONSET with a blank anchor is selected by C5; FIRST_ADMIN with a blank anchor uses the episode Start. Reported timing (C6) sits beside the value. CESSATION to a RECOVERY milestone is a C7 recovery interval. Send a query for every E-code.
B22: 5. Product evidence | C22: Product_Dossier (one row per extracted statement) and Parameter_Register (value, range, unit, population, half-life type, status, source).
B23: 6. Technical arithmetic | C23: PK_Exercises (Q1-Q5, Q7-Q11) and PD_Profile (Q6 teaching demonstration). Run only what the question needs. The common gate (Q1-Q5, Q7, Q8) needs four confirmations (model, half-life used, reference time, Parameter_Status) and every detail: the half-life type, population and source, the reference time in words and each input's Parameter_Status. Q8 shows a scenario range, never a midpoint or confidence interval. Q11 needs creatinine stability confirmed. The tools never calculate BSA; enter the BSA recorded at each administration.
B24: 7. Reviewer judgments | C24: Temporal_Profile, Biology_Review (four options, each with a rationale; none is a relatedness category), Dechallenge_Rechallenge, Alternatives_Followup.
B25: 8. Assessment_QC, Summary and Export | C25: Assessment_QC: narrative, method, unresolved issues and the counts of blocked and flagged interval rows. Summary: type a Case_ID (and a version, or blank for the latest) to see and print that case's records, intervals with flags, technical results, limitations and versions on one or two pages. Export: one row per result with the CALC-SPEC 1.1 Section 8 columns, export-safe text, Tool_Version, Calculation_Version and Export_Timestamp; copy the rows as values and save them as CSV UTF-8.
B27: Sheets
B28: Read_Me | C28: This page.
B29: Cases | C29: Input. One row per case version.
B30: Exposures | C30: Input. One row per exposure episode; Start, Stop and Restart are timepoints (Episode/START, /STOP, /RESTART).
B31: Administrations | C31: Input. One row per dose, dose change, other administration or infusion rate segment (start, end, rate); dose, BSA and date for Q10.
B32: Events | C32: Input. One row per event episode; Onset and First detection are timepoints (Episode/ONSET, /DETECTION). Onset precision LAB = laboratory-defined onset.
B33: Milestones | C33: Input. Tests, organ function, concentrations, interventions, recovery and other dated records.
B34: Drug_Event_Links | C34: Reviewer. Selected pairs with a reason (no automatic pairing).
B35: Intervals | C35: Derived. One row per link and anchor: value, unit, rule, sequence status, flags, messages, Parameter_Set, assumptions, limitations.
B36: Product_Dossier | C36: Input. Versioned product statements, timing-statement kind, label discrepancies.
B37: Parameter_Register | C37: Input. Parameters with status, population and source; a readiness check.
B38: PK_Exercises | C38: Derived. Q1-Q5 and Q7-Q11 with gates, Parameter_Set, assumptions, mandatory text and flags.
B39: PD_Profile | C39: Reviewer prompts; Q6 teaching demonstration (switch and use required; always I_TEACHING_DEMONSTRATION).
... B47: Lists | C47: Validation lists.
B49: Conventions
B50: Cells | C50: Yellow = input (unlocked). Grey = formula (locked). Blue rows at the bottom of a sheet are reserved and locked: they hold the fictional teaching cases and the verification vectors read by the Examples and Verification sheets. Copy them into the yellow rows with a new Case_ID to experiment.
B51: Date precision | C51: TIMESTAMP: Date, local Time and UTC offset (choose unknown if it is not recorded; C1 then uses local clock times with W_TZ_UNKNOWN). DATE: Date only, Time left blank (a date is never given a time). MONTH: Year and Month, expanded to the first and last day, leap years respected. YEAR: 1 January to 31 December. RANGE: earliest and latest dates as stated, with the source. LAB (event onset only): from the date of the last normal test to the date of the first abnormal test. A single date is never imputed from bounds.
B52: Dates and units | C52: Dates are displayed as day month year (10 January 2026); ISO 8601 forms are on Timepoints and Intervals. Units are in the column headers. Only the conversions of CALC-SPEC Section 6 are automatic; weeks, months and years are never converted to days. A blank unit gives E_MISSING_INPUT; an unlisted unit E_INVALID_UNIT.
...

Sheet Cases
A1: Cases: one row per case version
A2: Yellow cells are inputs; grey cells are locked formulas. Enter what the source says: original text, precision and bounds. Nothing is imputed (CALC-SPEC G2).
A3: INPUTS: one row per case version (follow-up adds a version; earlier rows stay) | J3: CHECKS
A4: Case_ID | B4: Case_Version | C4: Received date | D4: Setting | E4: Reviewer | F4: Review date | G4: Fictional or de-identified teaching case? | H4: Summary | I4: What this version adds | J4: Case key | K4: Key count | L4: Record check | M4: Check message
J5: =IF(A5="","",A5&"|"&B5) | K5: =IF(J5="",0,COUNTIF(nCASE_Key,J5)) -> 0 | L5: =IF(J5="","",IF(B5="","E_MISSING_INPUT",IF(K5>1,"E_DUPLICATE_ID",""))) | M5: =IF(L5="","",L5&": "&SUBSTITUTE(IFERROR(INDEX(nMSG_Text,MATCH(L5,nMSG_Code,0)),""),"[input]","a Case_Version"))
J6: =IF(A6="","",A6&"|"&B6) | K6: =IF(J6="",0,COUNTIF(nCASE_Key,J6)) -> 0 | L6: =IF(J6="","",IF(B6="","E_MISSING_INPUT",IF(K6>1,"E_DUPLICATE_ID",""))) | M6: =IF(L6="","",L6&": "&SUBSTITUTE(IFERROR(INDEX(nMSG_Text,MATCH(L6,nMSG_Code,0)),""),"[input]","a Case_Version"))
J7: =IF(A7="","",A7&"|"&B7) | K7: =IF(J7="",0,COUNTIF(nCASE_Key,J7)) -> 0 | L7: =IF(J7="","",IF(B7="","E_MISSING_INPUT",IF(K7>1,"E_DUPLICATE_ID",""))) | M7: =IF(L7="","",L7&": "&SUBSTITUTE(IFERROR(INDEX(nMSG_Text,MATCH(L7,nMSG_Code,0)),""),"[input]","a Case_Version"))
J8: =IF(A8="","",A8&"|"&B8) | K8: =IF(J8="",0,COUNTIF(nCASE_Key,J8)) -> 0 | L8: =IF(J8="","",IF(B8="","E_MISSING_INPUT",IF(K8>1,"E_DUPLICATE_ID",""))) | M8: =IF(L8="","",L8&": "&SUBSTITUTE(IFERROR(INDEX(nMSG_Text,MATCH(L8,nMSG_Code,0)),""),"[input]","a Case_Version"))
J9: =IF(A9="","",A9&"|"&B9) | K9: =IF(J9="",0,COUNTIF(nCASE_Key,J9)) -> 0 | L9: =IF(J9="","",IF(B9="","E_MISSING_INPUT",IF(K9>1,"E_DUPLICATE_ID",""))) | M9: =IF(L9="","",L9&": "&SUBSTITUTE(IFERROR(INDEX(nMSG_Text,MATCH(L9,nMSG_Code,0)),""),"[input]","a Case_Version"))
J10: =IF(A10="","",A10&"|"&B10) | K10: =IF(J10="",0,COUNTIF(nCASE_Key,J10)) -> 0 | L10: =IF(J10="","",IF(B10="","E_MISSING_INPUT",IF(K10>1,"E_DUPLICATE_ID",""))) | M10: =IF(L10="","",L10&": "&SUBSTITUTE(IFERROR(INDEX(nMSG_Text,MATCH(L10,nMSG_Code,0)),""),"[input]","a Case_Version"))
J11: =IF(A11="","",A11&"|"&B11) | K11: =IF(J11="",0,COUNTIF(nCASE_Key,J11)) -> 0 | L11: =IF(J11="","",IF(B11="","E_MISSING_INPUT",IF(K11>1,"E_DUPLICATE_ID",""))) | M11: =IF(L11="","",L11&": "&SUBSTITUTE(IFERROR(INDEX(nMSG_Text,MATCH(L11,nMSG_Code,0)),""),"[input]","a Case_Version"))
J12: =IF(A12="","",A12&"|"&B12) | K12: =IF(J12="",0,COUNTIF(nCASE_Key,J12)) -> 0 | L12: =IF(J12="","",IF(B12="","E_MISSING_INPUT",IF(K12>1,"E_DUPLICATE_ID",""))) | M12: =IF(L12="","",L12&": "&SUBSTITUTE(IFERROR(INDEX(nMSG_Text,MATCH(L12,nMSG_Code,0)),""),"[input]","a Case_Version"))
J13: =IF(A13="","",A13&"|"&B13) | K13: =IF(J13="",0,COUNTIF(nCASE_Key,J13)) -> 0 | L13: =IF(J13="","",IF(B13="","E_MISSING_INPUT",IF(K13>1,"E_DUPLICATE_ID",""))) | M13: =IF(L13="","",L13&": "&SUBSTITUTE(IFERROR(INDEX(nMSG_Text,MATCH(L13,nMSG_Code,0)),""),"[input]","a Case_Version"))
J14: =IF(A14="","",A14&"|"&B14) | K14: =IF(J14="",0,COUNTIF(nCASE_Key,J14)) -> 0 | L14: =IF(J14="","",IF(B14="","E_MISSING_INPUT",IF(K14>1,"E_DUPLICATE_ID",""))) | M14: =IF(L14="","",L14&": "&SUBSTITUTE(IFERROR(INDEX(nMSG_Text,MATCH(L14,nMSG_Code,0)),""),"[input]","a Case_Version"))
J15: =IF(A15="","",A15&"|"&B15) | K15: =IF(J15="",0,COUNTIF(nCASE_Key,J15)) -> 0 | L15: =IF(J15="","",IF(B15="","E_MISSING_INPUT",IF(K15>1,"E_DUPLICATE_ID",""))) | M15: =IF(L15="","",L15&": "&SUBSTITUTE(IFERROR(INDEX(nMSG_Text,MATCH(L15,nMSG_Code,0)),""),"[input]","a Case_Version"))
J16: =IF(A16="","",A16&"|"&B16) | K16: =IF(J16="",0,COUNTIF(nCASE_Key,J16)) -> 0 | L16: =IF(J16="","",IF(B16="","E_MISSING_INPUT",IF(K16>1,"E_DUPLICATE_ID",""))) | M16: =IF(L16="","",L16&": "&SUBSTITUTE(IFERROR(INDEX(nMSG_Text,MATCH(L16,nMSG_Code,0)),""),"[input]","a Case_Version"))
... J24: =IF(A24="","",A24&"|"&B24) | K24: =IF(J24="",0,COUNTIF(nCASE_Key,J24)) -> 0 | L24: =IF(J24="","",IF(B24="","E_MISSING_INPUT",IF(K24>1,"E_DUPLICATE_ID",""))) | M24: =IF(L24="","",L24&": "&SUBSTITUTE(IFERROR(INDEX(nMSG_Text,MATCH(L24,nMSG_Code,0)),""),"[input]","a Case_Version"))
A25: Reserved, locked rows: fictional teaching cases EX-C01 (case version 2), EX-C04 (version 2) and EX-C28 (version 2), read by the Examples sheet. Copy rows to the yellow area with a new Case_ID to experiment.
A26: EX-C01 | B26: 2 | C26: 46036 | D26: Hospital infusion (fictional) | G26: Yes | H26: Urticaria, wheeze and hypotension 15 minutes after the start of a first Drug A infusion (Chapter 3, Section 3.7). | I26: Version 2 (follow-up 14 January 2026) adds Drug B, the antiseptic, pump rate, first exposure, diagnosis and tryptase sample; version 1 facts unchanged. | J26: =IF(A26="","",A26&"|"&B26) -> EX-C01|2 | K26: =IF(J26="",0,COUNTIF(nCASE_Key,J26)) -> 1 | L26: =IF(J26="","",IF(B26="","E_MISSING_INPUT",IF(K26>1,"E_DUPLICATE_ID",""))) | M26: =IF(L26="","",L26&": "&SUBSTITUTE(IFERROR(INDEX(nMSG_Text,MATCH(L26,nMSG_Code,0)),""),"[input]","a Case_Version"))
A27: EX-C04 | B27: 2 | C27: 46223 | D27: Primary care and emergency department (fictional) | G27: Yes | H27: Nausea and symptomatic bradycardia on digoxin after renal deterioration (Chapter 11, Section 11.8; Chapter 23, Section 23.11). | I27: Version 2 (GP letter received 20 July 2026) adds dose, last dose time, ibuprofen, creatinine series, digoxin level with sample time and IV fluids. | J27: =IF(A27="","",A27&"|"&B27) -> EX-C04|2 | K27: =IF(J27="",0,COUNTIF(nCASE_Key,J27)) -> 1 | L27: =IF(J27="","",IF(B27="","E_MISSING_INPUT",IF(K27>1,"E_DUPLICATE_ID",""))) | M27: =IF(L27="","",L27&": "&SUBSTITUTE(IFERROR(INDEX(nMSG_Text,MATCH(L27,nMSG_Code,0)),""),"[input]","a Case_Version"))
A28: EX-C28 | B28: 2 | C28: 46188 | D28: Hematology and hepatology (fictional) | G28: Yes | H28: HBV reactivation months after completing rituximab (Chapter 20, Section 20.4; Chapter 23, Section 23.12). | I28: Version 2 (received 15 June 2026) adds cycle dates, serology, prophylaxis, HBV DNA monitoring, prednisolone course and B-cell/IgG results. | J28: =IF(A28="","",A28&"|"&B28) -> EX-C28|2 | K28: =IF(J28="",0,COUNTIF(nCASE_Key,J28)) -> 1 | L28: =IF(J28="","",IF(B28="","E_MISSING_INPUT",IF(K28>1,"E_DUPLICATE_ID",""))) | M28: =IF(L28="","",L28&": "&SUBSTITUTE(IFERROR(INDEX(nMSG_Text,MATCH(L28,nMSG_Code,0)),""),"[input]","a Case_Version"))
A29: Reserved, locked rows: CALC-SPEC 1.1 verification vectors (VEC-V01 ... VEC-V38), read by the Verification sheet. They use the same column formulas as your own rows.
A30: VEC-V01 | B30: 1 | G30: Yes | H30: CALC-SPEC 1.1 verification vector V01 (tto_calc_test_vectors_v1.1.json) | I30: Vector inputs as in the JSON file | J30: =IF(A30="","",A30&"|"&B30) -> VEC-V01|1 | K30: =IF(J30="",0,COUNTIF(nCASE_Key,J30)) -> 1 | L30: =IF(J30="","",IF(B30="","E_MISSING_INPUT",IF(K30>1,"E_DUPLICATE_ID",""))) | M30: =IF(L30="","",L30&": "&SUBSTITUTE(IFERROR(INDEX(nMSG_Text,MATCH(L30,nMSG_Code,0)),""),"[input]","a Case_Version"))
A31: VEC-V02 | B31: 1 | G31: Yes | H31: CALC-SPEC 1.1 verification vector V02 (tto_calc_test_vectors_v1.1.json) | I31: Vector inputs as in the JSON file | J31: =IF(A31="","",A31&"|"&B31) -> VEC-V02|1 | K31: =IF(J31="",0,COUNTIF(nCASE_Key,J31)) -> 1 | L31: =IF(J31="","",IF(B31="","E_MISSING_INPUT",IF(K31>1,"E_DUPLICATE_ID",""))) | M31: =IF(L31="","",L31&": "&SUBSTITUTE(IFERROR(INDEX(nMSG_Text,MATCH(L31,nMSG_Code,0)),""),"[input]","a Case_Version"))
A32: VEC-V03 | B32: 1 | G32: Yes | H32: CALC-SPEC 1.1 verification vector V03 (tto_calc_test_vectors_v1.1.json) | I32: Vector inputs as in the JSON file | J32: =IF(A32="","",A32&"|"&B32) -> VEC-V03|1 | K32: =IF(J32="",0,COUNTIF(nCASE_Key,J32)) -> 1 | L32: =IF(J32="","",IF(B32="","E_MISSING_INPUT",IF(K32>1,"E_DUPLICATE_ID",""))) | M32: =IF(L32="","",L32&": "&SUBSTITUTE(IFERROR(INDEX(nMSG_Text,MATCH(L32,nMSG_Code,0)),""),"[input]","a Case_Version"))
A33: VEC-V04 | B33: 1 | G33: Yes | H33: CALC-SPEC 1.1 verification vector V04 (tto_calc_test_vectors_v1.1.json) | I33: Vector inputs as in the JSON file | J33: =IF(A33="","",A33&"|"&B33) -> VEC-V04|1 | K33: =IF(J33="",0,COUNTIF(nCASE_Key,J33)) -> 1 | L33: =IF(J33="","",IF(B33="","E_MISSING_INPUT",IF(K33>1,"E_DUPLICATE_ID",""))) | M33: =IF(L33="","",L33&": "&SUBSTITUTE(IFERROR(INDEX(nMSG_Text,MATCH(L33,nMSG_Code,0)),""),"[input]","a Case_Version"))
A34: VEC-V05 | B34: 1 | G34: Yes | H34: CALC-SPEC 1.1 verification vector V05 (tto_calc_test_vectors_v1.1.json) | I34: Vector inputs as in the JSON file | J34: =IF(A34="","",A34&"|"&B34) -> VEC-V05|1 | K34: =IF(J34="",0,COUNTIF(nCASE_Key,J34)) -> 1 | L34: =IF(J34="","",IF(B34="","E_MISSING_INPUT",IF(K34>1,"E_DUPLICATE_ID",""))) | M34: =IF(L34="","",L34&": "&SUBSTITUTE(IFERROR(INDEX(nMSG_Text,MATCH(L34,nMSG_Code,0)),""),"[input]","a Case_Version"))
A35: VEC-V06 | B35: 1 | G35: Yes | H35: CALC-SPEC 1.1 verification vector V06 (tto_calc_test_vectors_v1.1.json) | I35: Vector inputs as in the JSON file | J35: =IF(A35="","",A35&"|"&B35) -> VEC-V06|1 | K35: =IF(J35="",0,COUNTIF(nCASE_Key,J35)) -> 1 | L35: =IF(J35="","",IF(B35="","E_MISSING_INPUT",IF(K35>1,"E_DUPLICATE_ID",""))) | M35: =IF(L35="","",L35&": "&SUBSTITUTE(IFERROR(INDEX(nMSG_Text,MATCH(L35,nMSG_Code,0)),""),"[input]","a Case_Version"))
A36: VEC-V07 | B36: 1 | G36: Yes | H36: CALC-SPEC 1.1 verification vector V07 (tto_calc_test_vectors_v1.1.json) | I36: Vector inputs as in the JSON file | J36: =IF(A36="","",A36&"|"&B36) -> VEC-V07|1 | K36: =IF(J36="",0,COUNTIF(nCASE_Key,J36)) -> 1 | L36: =IF(J36="","",IF(B36="","E_MISSING_INPUT",IF(K36>1,"E_DUPLICATE_ID",""))) | M36: =IF(L36="","",L36&": "&SUBSTITUTE(IFERROR(INDEX(nMSG_Text,MATCH(L36,nMSG_Code,0)),""),"[input]","a Case_Version"))
A37: VEC-V08 | B37: 1 | G37: Yes | H37: CALC-SPEC 1.1 verification vector V08 (tto_calc_test_vectors_v1.1.json) | I37: Vector inputs as in the JSON file | J37: =IF(A37="","",A37&"|"&B37) -> VEC-V08|1 | K37: =IF(J37="",0,COUNTIF(nCASE_Key,J37)) -> 1 | L37: =IF(J37="","",IF(B37="","E_MISSING_INPUT",IF(K37>1,"E_DUPLICATE_ID",""))) | M37: =IF(L37="","",L37&": "&SUBSTITUTE(IFERROR(INDEX(nMSG_Text,MATCH(L37,nMSG_Code,0)),""),"[input]","a Case_Version"))
A38: VEC-V09 | B38: 1 | G38: Yes | H38: CALC-SPEC 1.1 verification vector V09 (tto_calc_test_vectors_v1.1.json) | I38: Vector inputs as in the JSON file | J38: =IF(A38="","",A38&"|"&B38) -> VEC-V09|1 | K38: =IF(J38="",0,COUNTIF(nCASE_Key,J38)) -> 1 | L38: =IF(J38="","",IF(B38="","E_MISSING_INPUT",IF(K38>1,"E_DUPLICATE_ID",""))) | M38: =IF(L38="","",L38&": "&SUBSTITUTE(IFERROR(INDEX(nMSG_Text,MATCH(L38,nMSG_Code,0)),""),"[input]","a Case_Version"))
A39: VEC-V10 | B39: 1 | G39: Yes | H39: CALC-SPEC 1.1 verification vector V10 (tto_calc_test_vectors_v1.1.json) | I39: Vector inputs as in the JSON file | J39: =IF(A39="","",A39&"|"&B39) -> VEC-V10|1 | K39: =IF(J39="",0,COUNTIF(nCASE_Key,J39)) -> 1 | L39: =IF(J39="","",IF(B39="","E_MISSING_INPUT",IF(K39>1,"E_DUPLICATE_ID",""))) | M39: =IF(L39="","",L39&": "&SUBSTITUTE(IFERROR(INDEX(nMSG_Text,MATCH(L39,nMSG_Code,0)),""),"[input]","a Case_Version"))
A40: VEC-V11 | B40: 1 | G40: Yes | H40: CALC-SPEC 1.1 verification vector V11 (tto_calc_test_vectors_v1.1.json) | I40: Vector inputs as in the JSON file | J40: =IF(A40="","",A40&"|"&B40) -> VEC-V11|1 | K40: =IF(J40="",0,COUNTIF(nCASE_Key,J40)) -> 1 | L40: =IF(J40="","",IF(B40="","E_MISSING_INPUT",IF(K40>1,"E_DUPLICATE_ID",""))) | M40: =IF(L40="","",L40&": "&SUBSTITUTE(IFERROR(INDEX(nMSG_Text,MATCH(L40,nMSG_Code,0)),""),"[input]","a Case_Version"))
A41: VEC-V12 | B41: 1 | G41: Yes | H41: CALC-SPEC 1.1 verification vector V12 (tto_calc_test_vectors_v1.1.json) | I41: Vector inputs as in the JSON file | J41: =IF(A41="","",A41&"|"&B41) -> VEC-V12|1 | K41: =IF(J41="",0,COUNTIF(nCASE_Key,J41)) -> 1 | L41: =IF(J41="","",IF(B41="","E_MISSING_INPUT",IF(K41>1,"E_DUPLICATE_ID",""))) | M41: =IF(L41="","",L41&": "&SUBSTITUTE(IFERROR(INDEX(nMSG_Text,MATCH(L41,nMSG_Code,0)),""),"[input]","a Case_Version"))
... A67: VEC-V38 | B67: 1 | G67: Yes | H67: CALC-SPEC 1.1 verification vector V38 (tto_calc_test_vectors_v1.1.json) | I67: Vector inputs as in the JSON file | J67: =IF(A67="","",A67&"|"&B67) -> VEC-V38|1 | K67: =IF(J67="",0,COUNTIF(nCASE_Key,J67)) -> 1 | L67: =IF(J67="","",IF(B67="","E_MISSING_INPUT",IF(K67>1,"E_DUPLICATE_ID",""))) | M67: =IF(L67="","",L67&": "&SUBSTITUTE(IFERROR(INDEX(nMSG_Text,MATCH(L67,nMSG_Code,0)),""),"[input]","a Case_Version"))

Sheet Exposures
A1: Exposures: one row per exposure episode (Start, Stop and Restart are timepoints)
A2: Yellow cells are inputs; grey cells are locked formulas. Enter what the source says: original text, precision and bounds. Nothing is imputed (CALC-SPEC G2).
A3: INPUTS: one row per exposure episode | M3: Start (timepoint) | AD3: Stop (timepoint) | AU3: Restart (timepoint) | BL3: CHECKS
A4: Case_ID | B4: Case_Version | C4: Drug_ID | D4: Exposure_Episode_ID (timepoints: ID/START, ID/STOP, ID/RESTART) | E4: Product | F4: Role | G4: Route | H4: Dose (as reported) | I4: Dose unit | J4: Regimen (as reported) | K4: Missing-data reason (example codes) | L4: Notes | M4: Start: original text (as reported) | N4: Start: precision | O4: Start: date (TIMESTAMP, DATE) | P4: Start: local time hh:mm (TIMESTAMP only) | Q4: Start: UTC offset or unknown (TIMESTAMP) | R4: Start: year (MONTH, YEAR) | S4: Start: month 1-12 (MONTH) | T4: Start: earliest date (RANGE) | U4: Start: latest date (RANGE) | V4: Start: source (document, record) | W4: Start: check (E-code) | X4: Start: has time (1/0) | Y4: Start: offset known (1/0) | Z4: Start: lower bound (date) | AA4: Start: upper bound (date) | AB4: Start: local clock (minutes since 1900) | AC4: Start: UTC (minutes since 1900) | AD4: Stop: original text (as reported) | AE4: Stop: precision | AF4: Stop: date (TIMESTAMP, DATE) | AG4: Stop: local time hh:mm (TIMESTAMP only) | AH4: Stop: UTC offset or unknown (TIMESTAMP) | AI4: Stop: year (MONTH, YEAR) | AJ4: Stop: month 1-12 (MONTH) | AK4: Stop: earliest date (RANGE) | AL4: Stop: latest date (RANGE) | AM4: Stop: source (document, record) | AN4: Stop: check (E-code) | AO4: Stop: has time (1/0) | AP4: Stop: offset known (1/0) | AQ4: Stop: lower bound (date) | AR4: Stop: upper bound (date) | AS4: Stop: local clock (minutes since 1900) | AT4: Stop: UTC (minutes since 1900) | AU4: Restart: original text (as reported) | AV4: Restart: precision | AW4: Restart: date (TIMESTAMP, DATE) | AX4: Restart: local time hh:mm (TIMESTAMP only) | AY4: Restart: UTC offset or unknown (TIMESTAMP) | AZ4: Restart: year (MONTH, YEAR) | BA4: Restart: month 1-12 (MONTH) | BB4: Restart: earliest date (RANGE) | BC4: Restart: latest date (RANGE) | BD4: Restart: source (document, record) | BE4: Restart: check (E-code) | BF4: Restart: has time (1/0) | BG4: Restart: offset known (1/0) | BH4: Restart: lower bound (date) | BI4: Restart: upper bound (date) | BJ4: Restart: local clock (minutes since 1900) | BK4: Restart: UTC (minutes since 1900) | BL4: Exposure key | BM4: Key count | BN4: Record check (E-code) | BO4: Check message
W5: =IF(COUNTA(N5:U5)=0,"",IF(N5="","E_MISSING_INPUT",IF(N5="TIMESTAMP",IF(OR(O5="",P5="",Q5=""),"E_MISSING_INPUT",IF(OR(NOT(ISNUMBER(O5)),NOT(ISNUMBER(P5))),"E_INVALID_DATE",IF(OR(O5<>INT(O5),P5<0,P5>=1),"E_INVALID_DATE",IF(ISNA(MATCH(Q5,nLIST_Offset,0)),"E_INVALID_DATE","")))),IF(N5="DATE",IF(O5="","E_MISSING_INPUT",IF(NOT(ISNUMBER(O5)),"E_INVALID_DATE",IF(O5<>INT(O5),"E_INVALID_DATE",""))),IF(N5="MONTH",IF(OR(R5="",S5=""),"E_MISSING_INPUT",IF(OR(NOT(ISNUMBER(R5)),NOT(ISNUMBER(S5))),"E_INVALID_DATE",IF(OR(R5<1900,R5>9999,R5<>INT(R5),S5<1,S5>12,S5<>INT(S5)),"E_INVALID_DATE",""))),IF(N5="YEAR",IF(R5="","E_MISSING_INPUT",IF(NOT(ISNUMBER(R5)),"E_INVALID_DATE",IF(OR(R5<1900,R5>9999,R5<>INT(R5)),"E_INVALID_DATE",""))),IF(N5="RANGE",IF(OR(T5="",U5=""),"E_MISSING_INPUT",IF(OR(NOT(ISNUMBER(T5)),NOT(ISNUMBER(U5))),"E_INVALID_DATE",IF(OR(T5<>INT(T5),U5<>INT(U5)),"E_INVALID_DATE",IF(T5>U5,"E_REVERSED_BOUNDS","")))),"E_MISSING_INPUT"))))))) | X5: =IF(AND(W5="",N5="TIMESTAMP"),1,0) -> 0 | Y5: =IF(AND(X5=1,Q5<>"unknown"),1,0) -> 0 | Z5: =IF(OR(W5<>"",N5=""),"",IF(OR(N5="TIMESTAMP",N5="DATE"),O5,IF(N5="MONTH",DATE(R5,S5,1),IF(N5="YEAR",DATE(R5,1,1),T5)))) | AA5: =IF(OR(W5<>"",N5=""),"",IF(OR(N5="TIMESTAMP",N5="DATE"),O5,IF(N5="MONTH",EOMONTH(DATE(R5,S5,1),0),IF(N5="YEAR",DATE(R5,12,31),U5)))) | AB5: =IF(X5=1,O5*1440+ROUND(P5*1440,0),"") | AC5: =IF(Y5=1,AB5-(IF(LEFT(Q5,1)="-",-1,1)*(VALUE(MID(Q5,2,2))*60+VALUE(MID(Q5,5,2)))),"") | AN5: =IF(COUNTA(AE5:AL5)=0,"",IF(AE5="","E_MISSING_INPUT",IF(AE5="TIMESTAMP",IF(OR(AF5="",AG5="",AH5=""),"E_MISSING_INPUT",IF(OR(NOT(ISNUMBER(AF5)),NOT(ISNUMBER(AG5))),"E_INVALID_DATE",IF(OR(AF5<>INT(AF5),AG5<0,AG5>=1),"E_INVALID_DATE",IF(ISNA(MATCH(AH5,nLIST_Offset,0)),"E_INVALID_DATE","")))),IF(AE5="DATE",IF(AF5="","E_MISSING_INPUT",IF(NOT(ISNUMBER(AF5)),"E_INVALID_DATE",IF(AF5<>INT(AF5),"E_INVALID_DATE",""))),IF(AE5="MONTH",IF(OR(AI5="",AJ5=""),"E_MISSING_INPUT",IF(OR(NOT(ISNUMBER(AI5)),NOT(ISNUMBER(AJ5))),"E_INVALID_DATE",IF(OR(AI5<1900,AI5>9999,AI5<>INT(AI5),AJ5<1,AJ5>12,AJ5<>INT(AJ5)),"E_INVALID_DATE",""))),IF(AE5="YEAR",IF(AI5="","E_MISSING_INPUT",IF(NOT(ISNUMBER(AI5)),"E_INVALID_DATE",IF(OR(AI5<1900,AI5>9999,AI5<>INT(AI5)),"E_INVALID_DATE",""))),IF(AE5="RANGE",IF(OR(AK5="",AL5=""),"E_MISSING_INPUT",IF(OR(NOT(ISNUMBER(AK5)),NOT(ISNUMBER(AL5))),"E_INVALID_DATE",IF(OR(AK5<>INT(AK5),AL5<>INT(AL5)),"E_INVALID_DATE",IF(AK5>AL5,"E_REVERSED_BOUNDS","")))),"E_MISSING_INPUT"))))))) | AO5: =IF(AND(AN5="",AE5="TIMESTAMP"),1,0) -> 0 | AP5: =IF(AND(AO5=1,AH5<>"unknown"),1,0) -> 0 | AQ5: =IF(OR(AN5<>"",AE5=""),"",IF(OR(AE5="TIMESTAMP",AE5="DATE"),AF5,IF(AE5="MONTH",DATE(AI5,AJ5,1),IF(AE5="YEAR",DATE(AI5,1,1),AK5)))) | AR5: =IF(OR(AN5<>"",AE5=""),"",IF(OR(AE5="TIMESTAMP",AE5="DATE"),AF5,IF(AE5="MONTH",EOMONTH(DATE(AI5,AJ5,1),0),IF(AE5="YEAR",DATE(AI5,12,31),AL5)))) | AS5: =IF(AO5=1,AF5*1440+ROUND(AG5*1440,0),"") | AT5: =IF(AP5=1,AS5-(IF(LEFT(AH5,1)="-",-1,1)*(VALUE(MID(AH5,2,2))*60+VALUE(MID(AH5,5,2)))),"") | BE5: =IF(COUNTA(AV5:BC5)=0,"",IF(AV5="","E_MISSING_INPUT",IF(AV5="TIMESTAMP",IF(OR(AW5="",AX5="",AY5=""),"E_MISSING_INPUT",IF(OR(NOT(ISNUMBER(AW5)),NOT(ISNUMBER(AX5))),"E_INVALID_DATE",IF(OR(AW5<>INT(AW5),AX5<0,AX5>=1),"E_INVALID_DATE",IF(ISNA(MATCH(AY5,nLIST_Offset,0)),"E_INVALID_DATE","")))),IF(AV5="DATE",IF(AW5="","E_MISSING_INPUT",IF(NOT(ISNUMBER(AW5)),"E_INVALID_DATE",IF(AW5<>INT(AW5),"E_INVALID_DATE",""))),IF(AV5="MONTH",IF(OR(AZ5="",BA5=""),"E_MISSING_INPUT",IF(OR(NOT(ISNUMBER(AZ5)),NOT(ISNUMBER(BA5))),"E_INVALID_DATE",IF(OR(AZ5<1900,AZ5>9999,AZ5<>INT(AZ5),BA5<1,BA5>12,BA5<>INT(BA5)),"E_INVALID_DATE",""))),IF(AV5="YEAR",IF(AZ5="","E_MISSING_INPUT",IF(NOT(ISNUMBER(AZ5)),"E_INVALID_DATE",IF(OR(AZ5<1900,AZ5>9999,AZ5<>INT(AZ5)),"E_INVALID_DATE",""))),IF(AV5="RANGE",IF(OR(BB5="",BC5=""),"E_MISSING_INPUT",IF(OR(NOT(ISNUMBER(BB5)),NOT(ISNUMBER(BC5))),"E_INVALID_DATE",IF(OR(BB5<>INT(BB5),BC5<>INT(BC5)),"E_INVALID_DATE",IF(BB5>BC5,"E_REVERSED_BOUNDS","")))),"E_MISSING_INPUT"))))))) | BF5: =IF(AND(BE5="",AV5="TIMESTAMP"),1,0) -> 0 | BG5: =IF(AND(BF5=1,AY5<>"unknown"),1,0) -> 0 | BH5: =IF(OR(BE5<>"",AV5=""),"",IF(OR(AV5="TIMESTAMP",AV5="DATE"),AW5,IF(AV5="MONTH",DATE(AZ5,BA5,1),IF(AV5="YEAR",DATE(AZ5,1,1),BB5)))) | BI5: =IF(OR(BE5<>"",AV5=""),"",IF(OR(AV5="TIMESTAMP",AV5="DATE"),AW5,IF(AV5="MONTH",EOMONTH(DATE(AZ5,BA5,1),0),IF(AV5="YEAR",DATE(AZ5,12,31),BC5)))) | BJ5: =IF(BF5=1,AW5*1440+ROUND(AX5*1440,0),"") | BK5: =IF(BG5=1,BJ5-(IF(LEFT(AY5,1)="-",-1,1)*(VALUE(MID(AY5,2,2))*60+VALUE(MID(AY5,5,2)))),"") | BL5: =IF(D5="","",A5&"|"&B5&"|"&D5) | BM5: =IF(BL5="",0,COUNTIF(nEXP_Key,BL5)) -> 0 | BN5: =IF(D5="",IF(COUNTA(C5,E5,N5,O5)>0,"E_MISSING_INPUT",""),IF(BM5>1,"E_DUPLICATE_ID",IF(W5<>"",W5,IF(AN5<>"",AN5,BE5)))) | BO5: =IF(BN5="","",BN5&": "&SUBSTITUTE(IFERROR(INDEX(nMSG_Text,MATCH(BN5,nMSG_Code,0)),""),"[input]",IF(D5="","an Exposure_Episode_ID","the date fields required by the selected precision")))
W6: =IF(COUNTA(N6:U6)=0,"",IF(N6="","E_MISSING_INPUT",IF(N6="TIMESTAMP",IF(OR(O6="",P6="",Q6=""),"E_MISSING_INPUT",IF(OR(NOT(ISNUMBER(O6)),NOT(ISNUMBER(P6))),"E_INVALID_DATE",IF(OR(O6<>INT(O6),P6<0,P6>=1),"E_INVALID_DATE",IF(ISNA(MATCH(Q6,nLIST_Offset,0)),"E_INVALID_DATE","")))),IF(N6="DATE",IF(O6="","E_MISSING_INPUT",IF(NOT(ISNUMBER(O6)),"E_INVALID_DATE",IF(O6<>INT(O6),"E_INVALID_DATE",""))),IF(N6="MONTH",IF(OR(R6="",S6=""),"E_MISSING_INPUT",IF(OR(NOT(ISNUMBER(R6)),NOT(ISNUMBER(S6))),"E_INVALID_DATE",IF(OR(R6<1900,R6>9999,R6<>INT(R6),S6<1,S6>12,S6<>INT(S6)),"E_INVALID_DATE",""))),IF(N6="YEAR",IF(R6="","E_MISSING_INPUT",IF(NOT(ISNUMBER(R6)),"E_INVALID_DATE",IF(OR(R6<1900,R6>9999,R6<>INT(R6)),"E_INVALID_DATE",""))),IF(N6="RANGE",IF(OR(T6="",U6=""),"E_MISSING_INPUT",IF(OR(NOT(ISNUMBER(T6)),NOT(ISNUMBER(U6))),"E_INVALID_DATE",IF(OR(T6<>INT(T6),U6<>INT(U6)),"E_INVALID_DATE",IF(T6>U6,"E_REVERSED_BOUNDS","")))),"E_MISSING_INPUT"))))))) | X6: =IF(AND(W6="",N6="TIMESTAMP"),1,0) -> 0 | Y6: =IF(AND(X6=1,Q6<>"unknown"),1,0) -> 0 | Z6: =IF(OR(W6<>"",N6=""),"",IF(OR(N6="TIMESTAMP",N6="DATE"),O6,IF(N6="MONTH",DATE(R6,S6,1),IF(N6="YEAR",DATE(R6,1,1),T6)))) | AA6: =IF(OR(W6<>"",N6=""),"",IF(OR(N6="TIMESTAMP",N6="DATE"),O6,IF(N6="MONTH",EOMONTH(DATE(R6,S6,1),0),IF(N6="YEAR",DATE(R6,12,31),U6)))) | AB6: =IF(X6=1,O6*1440+ROUND(P6*1440,0),"") | AC6: =IF(Y6=1,AB6-(IF(LEFT(Q6,1)="-",-1,1)*(VALUE(MID(Q6,2,2))*60+VALUE(MID(Q6,5,2)))),"") | AN6: =IF(COUNTA(AE6:AL6)=0,"",IF(AE6="","E_MISSING_INPUT",IF(AE6="TIMESTAMP",IF(OR(AF6="",AG6="",AH6=""),"E_MISSING_INPUT",IF(OR(NOT(ISNUMBER(AF6)),NOT(ISNUMBER(AG6))),"E_INVALID_DATE",IF(OR(AF6<>INT(AF6),AG6<0,AG6>=1),"E_INVALID_DATE",IF(ISNA(MATCH(AH6,nLIST_Offset,0)),"E_INVALID_DATE","")))),IF(AE6="DATE",IF(AF6="","E_MISSING_INPUT",IF(NOT(ISNUMBER(AF6)),"E_INVALID_DATE",IF(AF6<>INT(AF6),"E_INVALID_DATE",""))),IF(AE6="MONTH",IF(OR(AI6="",AJ6=""),"E_MISSING_INPUT",IF(OR(NOT(ISNUMBER(AI6)),NOT(ISNUMBER(AJ6))),"E_INVALID_DATE",IF(OR(AI6<1900,AI6>9999,AI6<>INT(AI6),AJ6<1,AJ6>12,AJ6<>INT(AJ6)),"E_INVALID_DATE",""))),IF(AE6="YEAR",IF(AI6="","E_MISSING_INPUT",IF(NOT(ISNUMBER(AI6)),"E_INVALID_DATE",IF(OR(AI6<1900,AI6>9999,AI6<>INT(AI6)),"E_INVALID_DATE",""))),IF(AE6="RANGE",IF(OR(AK6="",AL6=""),"E_MISSING_INPUT",IF(OR(NOT(ISNUMBER(AK6)),NOT(ISNUMBER(AL6))),"E_INVALID_DATE",IF(OR(AK6<>INT(AK6),AL6<>INT(AL6)),"E_INVALID_DATE",IF(AK6>AL6,"E_REVERSED_BOUNDS","")))),"E_MISSING_INPUT"))))))) | AO6: =IF(AND(AN6="",AE6="TIMESTAMP"),1,0) -> 0 | AP6: =IF(AND(AO6=1,AH6<>"unknown"),1,0) -> 0 | AQ6: =IF(OR(AN6<>"",AE6=""),"",IF(OR(AE6="TIMESTAMP",AE6="DATE"),AF6,IF(AE6="MONTH",DATE(AI6,AJ6,1),IF(AE6="YEAR",DATE(AI6,1,1),AK6)))) | AR6: =IF(OR(AN6<>"",AE6=""),"",IF(OR(AE6="TIMESTAMP",AE6="DATE"),AF6,IF(AE6="MONTH",EOMONTH(DATE(AI6,AJ6,1),0),IF(AE6="YEAR",DATE(AI6,12,31),AL6)))) | AS6: =IF(AO6=1,AF6*1440+ROUND(AG6*1440,0),"") | AT6: =IF(AP6=1,AS6-(IF(LEFT(AH6,1)="-",-1,1)*(VALUE(MID(AH6,2,2))*60+VALUE(MID(AH6,5,2)))),"") | BE6: =IF(COUNTA(AV6:BC6)=0,"",IF(AV6="","E_MISSING_INPUT",IF(AV6="TIMESTAMP",IF(OR(AW6="",AX6="",AY6=""),"E_MISSING_INPUT",IF(OR(NOT(ISNUMBER(AW6)),NOT(ISNUMBER(AX6))),"E_INVALID_DATE",IF(OR(AW6<>INT(AW6),AX6<0,AX6>=1),"E_INVALID_DATE",IF(ISNA(MATCH(AY6,nLIST_Offset,0)),"E_INVALID_DATE","")))),IF(AV6="DATE",IF(AW6="","E_MISSING_INPUT",IF(NOT(ISNUMBER(AW6)),"E_INVALID_DATE",IF(AW6<>INT(AW6),"E_INVALID_DATE",""))),IF(AV6="MONTH",IF(OR(AZ6="",BA6=""),"E_MISSING_INPUT",IF(OR(NOT(ISNUMBER(AZ6)),NOT(ISNUMBER(BA6))),"E_INVALID_DATE",IF(OR(AZ6<1900,AZ6>9999,AZ6<>INT(AZ6),BA6<1,BA6>12,BA6<>INT(BA6)),"E_INVALID_DATE",""))),IF(AV6="YEAR",IF(AZ6="","E_MISSING_INPUT",IF(NOT(ISNUMBER(AZ6)),"E_INVALID_DATE",IF(OR(AZ6<1900,AZ6>9999,AZ6<>INT(AZ6)),"E_INVALID_DATE",""))),IF(AV6="RANGE",IF(OR(BB6="",BC6=""),"E_MISSING_INPUT",IF(OR(NOT(ISNUMBER(BB6)),NOT(ISNUMBER(BC6))),"E_INVALID_DATE",IF(OR(BB6<>INT(BB6),BC6<>INT(BC6)),"E_INVALID_DATE",IF(BB6>BC6,"E_REVERSED_BOUNDS","")))),"E_MISSING_INPUT"))))))) | BF6: =IF(AND(BE6="",AV6="TIMESTAMP"),1,0) -> 0 | BG6: =IF(AND(BF6=1,AY6<>"unknown"),1,0) -> 0 | BH6: =IF(OR(BE6<>"",AV6=""),"",IF(OR(AV6="TIMESTAMP",AV6="DATE"),AW6,IF(AV6="MONTH",DATE(AZ6,BA6,1),IF(AV6="YEAR",DATE(AZ6,1,1),BB6)))) | BI6: =IF(OR(BE6<>"",AV6=""),"",IF(OR(AV6="TIMESTAMP",AV6="DATE"),AW6,IF(AV6="MONTH",EOMONTH(DATE(AZ6,BA6,1),0),IF(AV6="YEAR",DATE(AZ6,12,31),BC6)))) | BJ6: =IF(BF6=1,AW6*1440+ROUND(AX6*1440,0),"") | BK6: =IF(BG6=1,BJ6-(IF(LEFT(AY6,1)="-",-1,1)*(VALUE(MID(AY6,2,2))*60+VALUE(MID(AY6,5,2)))),"") | BL6: =IF(D6="","",A6&"|"&B6&"|"&D6) | BM6: =IF(BL6="",0,COUNTIF(nEXP_Key,BL6)) -> 0 | BN6: =IF(D6="",IF(COUNTA(C6,E6,N6,O6)>0,"E_MISSING_INPUT",""),IF(BM6>1,"E_DUPLICATE_ID",IF(W6<>"",W6,IF(AN6<>"",AN6,BE6)))) | BO6: =IF(BN6="","",BN6&": "&SUBSTITUTE(IFERROR(INDEX(nMSG_Text,MATCH(BN6,nMSG_Code,0)),""),"[input]",IF(D6="","an Exposure_Episode_ID","the date fields required by the selected precision")))
W7: =IF(COUNTA(N7:U7)=0,"",IF(N7="","E_MISSING_INPUT",IF(N7="TIMESTAMP",IF(OR(O7="",P7="",Q7=""),"E_MISSING_INPUT",IF(OR(NOT(ISNUMBER(O7)),NOT(ISNUMBER(P7))),"E_INVALID_DATE",IF(OR(O7<>INT(O7),P7<0,P7>=1),"E_INVALID_DATE",IF(ISNA(MATCH(Q7,nLIST_Offset,0)),"E_INVALID_DATE","")))),IF(N7="DATE",IF(O7="","E_MISSING_INPUT",IF(NOT(ISNUMBER(O7)),"E_INVALID_DATE",IF(O7<>INT(O7),"E_INVALID_DATE",""))),IF(N7="MONTH",IF(OR(R7="",S7=""),"E_MISSING_INPUT",IF(OR(NOT(ISNUMBER(R7)),NOT(ISNUMBER(S7))),"E_INVALID_DATE",IF(OR(R7<1900,R7>9999,R7<>INT(R7),S7<1,S7>12,S7<>INT(S7)),"E_INVALID_DATE",""))),IF(N7="YEAR",IF(R7="","E_MISSING_INPUT",IF(NOT(ISNUMBER(R7)),"E_INVALID_DATE",IF(OR(R7<1900,R7>9999,R7<>INT(R7)),"E_INVALID_DATE",""))),IF(N7="RANGE",IF(OR(T7="",U7=""),"E_MISSING_INPUT",IF(OR(NOT(ISNUMBER(T7)),NOT(ISNUMBER(U7))),"E_INVALID_DATE",IF(OR(T7<>INT(T7),U7<>INT(U7)),"E_INVALID_DATE",IF(T7>U7,"E_REVERSED_BOUNDS","")))),"E_MISSING_INPUT"))))))) | X7: =IF(AND(W7="",N7="TIMESTAMP"),1,0) -> 0 | Y7: =IF(AND(X7=1,Q7<>"unknown"),1,0) -> 0 | Z7: =IF(OR(W7<>"",N7=""),"",IF(OR(N7="TIMESTAMP",N7="DATE"),O7,IF(N7="MONTH",DATE(R7,S7,1),IF(N7="YEAR",DATE(R7,1,1),T7)))) | AA7: =IF(OR(W7<>"",N7=""),"",IF(OR(N7="TIMESTAMP",N7="DATE"),O7,IF(N7="MONTH",EOMONTH(DATE(R7,S7,1),0),IF(N7="YEAR",DATE(R7,12,31),U7)))) | AB7: =IF(X7=1,O7*1440+ROUND(P7*1440,0),"") | AC7: =IF(Y7=1,AB7-(IF(LEFT(Q7,1)="-",-1,1)*(VALUE(MID(Q7,2,2))*60+VALUE(MID(Q7,5,2)))),"") | AN7: =IF(COUNTA(AE7:AL7)=0,"",IF(AE7="","E_MISSING_INPUT",IF(AE7="TIMESTAMP",IF(OR(AF7="",AG7="",AH7=""),"E_MISSING_INPUT",IF(OR(NOT(ISNUMBER(AF7)),NOT(ISNUMBER(AG7))),"E_INVALID_DATE",IF(OR(AF7<>INT(AF7),AG7<0,AG7>=1),"E_INVALID_DATE",IF(ISNA(MATCH(AH7,nLIST_Offset,0)),"E_INVALID_DATE","")))),IF(AE7="DATE",IF(AF7="","E_MISSING_INPUT",IF(NOT(ISNUMBER(AF7)),"E_INVALID_DATE",IF(AF7<>INT(AF7),"E_INVALID_DATE",""))),IF(AE7="MONTH",IF(OR(AI7="",AJ7=""),"E_MISSING_INPUT",IF(OR(NOT(ISNUMBER(AI7)),NOT(ISNUMBER(AJ7))),"E_INVALID_DATE",IF(OR(AI7<1900,AI7>9999,AI7<>INT(AI7),AJ7<1,AJ7>12,AJ7<>INT(AJ7)),"E_INVALID_DATE",""))),IF(AE7="YEAR",IF(AI7="","E_MISSING_INPUT",IF(NOT(ISNUMBER(AI7)),"E_INVALID_DATE",IF(OR(AI7<1900,AI7>9999,AI7<>INT(AI7)),"E_INVALID_DATE",""))),IF(AE7="RANGE",IF(OR(AK7="",AL7=""),"E_MISSING_INPUT",IF(OR(NOT(ISNUMBER(AK7)),NOT(ISNUMBER(AL7))),"E_INVALID_DATE",IF(OR(AK7<>INT(AK7),AL7<>INT(AL7)),"E_INVALID_DATE",IF(AK7>AL7,"E_REVERSED_BOUNDS","")))),"E_MISSING_INPUT"))))))) | AO7: =IF(AND(AN7="",AE7="TIMESTAMP"),1,0) -> 0 | AP7: =IF(AND(AO7=1,AH7<>"unknown"),1,0) -> 0 | AQ7: =IF(OR(AN7<>"",AE7=""),"",IF(OR(AE7="TIMESTAMP",AE7="DATE"),AF7,IF(AE7="MONTH",DATE(AI7,AJ7,1),IF(AE7="YEAR",DATE(AI7,1,1),AK7)))) | AR7: =IF(OR(AN7<>"",AE7=""),"",IF(OR(AE7="TIMESTAMP",AE7="DATE"),AF7,IF(AE7="MONTH",EOMONTH(DATE(AI7,AJ7,1),0),IF(AE7="YEAR",DATE(AI7,12,31),AL7)))) | AS7: =IF(AO7=1,AF7*1440+ROUND(AG7*1440,0),"") | AT7: =IF(AP7=1,AS7-(IF(LEFT(AH7,1)="-",-1,1)*(VALUE(MID(AH7,2,2))*60+VALUE(MID(AH7,5,2)))),"") | BE7: =IF(COUNTA(AV7:BC7)=0,"",IF(AV7="","E_MISSING_INPUT",IF(AV7="TIMESTAMP",IF(OR(AW7="",AX7="",AY7=""),"E_MISSING_INPUT",IF(OR(NOT(ISNUMBER(AW7)),NOT(ISNUMBER(AX7))),"E_INVALID_DATE",IF(OR(AW7<>INT(AW7),AX7<0,AX7>=1),"E_INVALID_DATE",IF(ISNA(MATCH(AY7,nLIST_Offset,0)),"E_INVALID_DATE","")))),IF(AV7="DATE",IF(AW7="","E_MISSING_INPUT",IF(NOT(ISNUMBER(AW7)),"E_INVALID_DATE",IF(AW7<>INT(AW7),"E_INVALID_DATE",""))),IF(AV7="MONTH",IF(OR(AZ7="",BA7=""),"E_MISSING_INPUT",IF(OR(NOT(ISNUMBER(AZ7)),NOT(ISNUMBER(BA7))),"E_INVALID_DATE",IF(OR(AZ7<1900,AZ7>9999,AZ7<>INT(AZ7),BA7<1,BA7>12,BA7<>INT(BA7)),"E_INVALID_DATE",""))),IF(AV7="YEAR",IF(AZ7="","E_MISSING_INPUT",IF(NOT(ISNUMBER(AZ7)),"E_INVALID_DATE",IF(OR(AZ7<1900,AZ7>9999,AZ7<>INT(AZ7)),"E_INVALID_DATE",""))),IF(AV7="RANGE",IF(OR(BB7="",BC7=""),"E_MISSING_INPUT",IF(OR(NOT(ISNUMBER(BB7)),NOT(ISNUMBER(BC7))),"E_INVALID_DATE",IF(OR(BB7<>INT(BB7),BC7<>INT(BC7)),"E_INVALID_DATE",IF(BB7>BC7,"E_REVERSED_BOUNDS","")))),"E_MISSING_INPUT"))))))) | BF7: =IF(AND(BE7="",AV7="TIMESTAMP"),1,0) -> 0 | BG7: =IF(AND(BF7=1,AY7<>"unknown"),1,0) -> 0 | BH7: =IF(OR(BE7<>"",AV7=""),"",IF(OR(AV7="TIMESTAMP",AV7="DATE"),AW7,IF(AV7="MONTH",DATE(AZ7,BA7,1),IF(AV7="YEAR",DATE(AZ7,1,1),BB7)))) | BI7: =IF(OR(BE7<>"",AV7=""),"",IF(OR(AV7="TIMESTAMP",AV7="DATE"),AW7,IF(AV7="MONTH",EOMONTH(DATE(AZ7,BA7,1),0),IF(AV7="YEAR",DATE(AZ7,12,31),BC7)))) | BJ7: =IF(BF7=1,AW7*1440+ROUND(AX7*1440,0),"") | BK7: =IF(BG7=1,BJ7-(IF(LEFT(AY7,1)="-",-1,1)*(VALUE(MID(AY7,2,2))*60+VALUE(MID(AY7,5,2)))),"") | BL7: =IF(D7="","",A7&"|"&B7&"|"&D7) | BM7: =IF(BL7="",0,COUNTIF(nEXP_Key,BL7)) -> 0 | BN7: =IF(D7="",IF(COUNTA(C7,E7,N7,O7)>0,"E_MISSING_INPUT",""),IF(BM7>1,"E_DUPLICATE_ID",IF(W7<>"",W7,IF(AN7<>"",AN7,BE7)))) | BO7: =IF(BN7="","",BN7&": "&SUBSTITUTE(IFERROR(INDEX(nMSG_Text,MATCH(BN7,nMSG_Code,0)),""),"[input]",IF(D7="","an Exposure_Episode_ID","the date fields required by the selected precision")))
W8: =IF(COUNTA(N8:U8)=0,"",IF(N8="","E_MISSING_INPUT",IF(N8="TIMESTAMP",IF(OR(O8="",P8="",Q8=""),"E_MISSING_INPUT",IF(OR(NOT(ISNUMBER(O8)),NOT(ISNUMBER(P8))),"E_INVALID_DATE",IF(OR(O8<>INT(O8),P8<0,P8>=1),"E_INVALID_DATE",IF(ISNA(MATCH(Q8,nLIST_Offset,0)),"E_INVALID_DATE","")))),IF(N8="DATE",IF(O8="","E_MISSING_INPUT",IF(NOT(ISNUMBER(O8)),"E_INVALID_DATE",IF(O8<>INT(O8),"E_INVALID_DATE",""))),IF(N8="MONTH",IF(OR(R8="",S8=""),"E_MISSING_INPUT",IF(OR(NOT(ISNUMBER(R8)),NOT(ISNUMBER(S8))),"E_INVALID_DATE",IF(OR(R8<1900,R8>9999,R8<>INT(R8),S8<1,S8>12,S8<>INT(S8)),"E_INVALID_DATE",""))),IF(N8="YEAR",IF(R8="","E_MISSING_INPUT",IF(NOT(ISNUMBER(R8)),"E_INVALID_DATE",IF(OR(R8<1900,R8>9999,R8<>INT(R8)),"E_INVALID_DATE",""))),IF(N8="RANGE",IF(OR(T8="",U8=""),"E_MISSING_INPUT",IF(OR(NOT(ISNUMBER(T8)),NOT(ISNUMBER(U8))),"E_INVALID_DATE",IF(OR(T8<>INT(T8),U8<>INT(U8)),"E_INVALID_DATE",IF(T8>U8,"E_REVERSED_BOUNDS","")))),"E_MISSING_INPUT"))))))) | X8: =IF(AND(W8="",N8="TIMESTAMP"),1,0) -> 0 | Y8: =IF(AND(X8=1,Q8<>"unknown"),1,0) -> 0 | Z8: =IF(OR(W8<>"",N8=""),"",IF(OR(N8="TIMESTAMP",N8="DATE"),O8,IF(N8="MONTH",DATE(R8,S8,1),IF(N8="YEAR",DATE(R8,1,1),T8)))) | AA8: =IF(OR(W8<>"",N8=""),"",IF(OR(N8="TIMESTAMP",N8="DATE"),O8,IF(N8="MONTH",EOMONTH(DATE(R8,S8,1),0),IF(N8="YEAR",DATE(R8,12,31),U8)))) | AB8: =IF(X8=1,O8*1440+ROUND(P8*1440,0),"") | AC8: =IF(Y8=1,AB8-(IF(LEFT(Q8,1)="-",-1,1)*(VALUE(MID(Q8,2,2))*60+VALUE(MID(Q8,5,2)))),"") | AN8: =IF(COUNTA(AE8:AL8)=0,"",IF(AE8="","E_MISSING_INPUT",IF(AE8="TIMESTAMP",IF(OR(AF8="",AG8="",AH8=""),"E_MISSING_INPUT",IF(OR(NOT(ISNUMBER(AF8)),NOT(ISNUMBER(AG8))),"E_INVALID_DATE",IF(OR(AF8<>INT(AF8),AG8<0,AG8>=1),"E_INVALID_DATE",IF(ISNA(MATCH(AH8,nLIST_Offset,0)),"E_INVALID_DATE","")))),IF(AE8="DATE",IF(AF8="","E_MISSING_INPUT",IF(NOT(ISNUMBER(AF8)),"E_INVALID_DATE",IF(AF8<>INT(AF8),"E_INVALID_DATE",""))),IF(AE8="MONTH",IF(OR(AI8="",AJ8=""),"E_MISSING_INPUT",IF(OR(NOT(ISNUMBER(AI8)),NOT(ISNUMBER(AJ8))),"E_INVALID_DATE",IF(OR(AI8<1900,AI8>9999,AI8<>INT(AI8),AJ8<1,AJ8>12,AJ8<>INT(AJ8)),"E_INVALID_DATE",""))),IF(AE8="YEAR",IF(AI8="","E_MISSING_INPUT",IF(NOT(ISNUMBER(AI8)),"E_INVALID_DATE",IF(OR(AI8<1900,AI8>9999,AI8<>INT(AI8)),"E_INVALID_DATE",""))),IF(AE8="RANGE",IF(OR(AK8="",AL8=""),"E_MISSING_INPUT",IF(OR(NOT(ISNUMBER(AK8)),NOT(ISNUMBER(AL8))),"E_INVALID_DATE",IF(OR(AK8<>INT(AK8),AL8<>INT(AL8)),"E_INVALID_DATE",IF(AK8>AL8,"E_REVERSED_BOUNDS","")))),"E_MISSING_INPUT"))))))) | AO8: =IF(AND(AN8="",AE8="TIMESTAMP"),1,0) -> 0 | AP8: =IF(AND(AO8=1,AH8<>"unknown"),1,0) -> 0 | AQ8: =IF(OR(AN8<>"",AE8=""),"",IF(OR(AE8="TIMESTAMP",AE8="DATE"),AF8,IF(AE8="MONTH",DATE(AI8,AJ8,1),IF(AE8="YEAR",DATE(AI8,1,1),AK8)))) | AR8: =IF(OR(AN8<>"",AE8=""),"",IF(OR(AE8="TIMESTAMP",AE8="DATE"),AF8,IF(AE8="MONTH",EOMONTH(DATE(AI8,AJ8,1),0),IF(AE8="YEAR",DATE(AI8,12,31),AL8)))) | AS8: =IF(AO8=1,AF8*1440+ROUND(AG8*1440,0),"") | AT8: =IF(AP8=1,AS8-(IF(LEFT(AH8,1)="-",-1,1)*(VALUE(MID(AH8,2,2))*60+VALUE(MID(AH8,5,2)))),"") | BE8: =IF(COUNTA(AV8:BC8)=0,"",IF(AV8="","E_MISSING_INPUT",IF(AV8="TIMESTAMP",IF(OR(AW8="",AX8="",AY8=""),"E_MISSING_INPUT",IF(OR(NOT(ISNUMBER(AW8)),NOT(ISNUMBER(AX8))),"E_INVALID_DATE",IF(OR(AW8<>INT(AW8),AX8<0,AX8>=1),"E_INVALID_DATE",IF(ISNA(MATCH(AY8,nLIST_Offset,0)),"E_INVALID_DATE","")))),IF(AV8="DATE",IF(AW8="","E_MISSING_INPUT",IF(NOT(ISNUMBER(AW8)),"E_INVALID_DATE",IF(AW8<>INT(AW8),"E_INVALID_DATE",""))),IF(AV8="MONTH",IF(OR(AZ8="",BA8=""),"E_MISSING_INPUT",IF(OR(NOT(ISNUMBER(AZ8)),NOT(ISNUMBER(BA8))),"E_INVALID_DATE",IF(OR(AZ8<1900,AZ8>9999,AZ8<>INT(AZ8),BA8<1,BA8>12,BA8<>INT(BA8)),"E_INVALID_DATE",""))),IF(AV8="YEAR",IF(AZ8="","E_MISSING_INPUT",IF(NOT(ISNUMBER(AZ8)),"E_INVALID_DATE",IF(OR(AZ8<1900,AZ8>9999,AZ8<>INT(AZ8)),"E_INVALID_DATE",""))),IF(AV8="RANGE",IF(OR(BB8="",BC8=""),"E_MISSING_INPUT",IF(OR(NOT(ISNUMBER(BB8)),NOT(ISNUMBER(BC8))),"E_INVALID_DATE",IF(OR(BB8<>INT(BB8),BC8<>INT(BC8)),"E_INVALID_DATE",IF(BB8>BC8,"E_REVERSED_BOUNDS","")))),"E_MISSING_INPUT"))))))) | BF8: =IF(AND(BE8="",AV8="TIMESTAMP"),1,0) -> 0 | BG8: =IF(AND(BF8=1,AY8<>"unknown"),1,0) -> 0 | BH8: =IF(OR(BE8<>"",AV8=""),"",IF(OR(AV8="TIMESTAMP",AV8="DATE"),AW8,IF(AV8="MONTH",DATE(AZ8,BA8,1),IF(AV8="YEAR",DATE(AZ8,1,1),BB8)))) | BI8: =IF(OR(BE8<>"",AV8=""),"",IF(OR(AV8="TIMESTAMP",AV8="DATE"),AW8,IF(AV8="MONTH",EOMONTH(DATE(AZ8,BA8,1),0),IF(AV8="YEAR",DATE(AZ8,12,31),BC8)))) | BJ8: =IF(BF8=1,AW8*1440+ROUND(AX8*1440,0),"") | BK8: =IF(BG8=1,BJ8-(IF(LEFT(AY8,1)="-",-1,1)*(VALUE(MID(AY8,2,2))*60+VALUE(MID(AY8,5,2)))),"") | BL8: =IF(D8="","",A8&"|"&B8&"|"&D8) | BM8: =IF(BL8="",0,COUNTIF(nEXP_Key,BL8)) -> 0 | BN8: =IF(D8="",IF(COUNTA(C8,E8,N8,O8)>0,"E_MISSING_INPUT",""),IF(BM8>1,"E_DUPLICATE_ID",IF(W8<>"",W8,IF(AN8<>"",AN8,BE8)))) | BO8: =IF(BN8="","",BN8&": "&SUBSTITUTE(IFERROR(INDEX(nMSG_Text,MATCH(BN8,nMSG_Code,0)),""),"[input]",IF(D8="","an Exposure_Episode_ID","the date fields required by the selected precision")))
W9: =IF(COUNTA(N9:U9)=0,"",IF(N9="","E_MISSING_INPUT",IF(N9="TIMESTAMP",IF(OR(O9="",P9="",Q9=""),"E_MISSING_INPUT",IF(OR(NOT(ISNUMBER(O9)),NOT(ISNUMBER(P9))),"E_INVALID_DATE",IF(OR(O9<>INT(O9),P9<0,P9>=1),"E_INVALID_DATE",IF(ISNA(MATCH(Q9,nLIST_Offset,0)),"E_INVALID_DATE","")))),IF(N9="DATE",IF(O9="","E_MISSING_INPUT",IF(NOT(ISNUMBER(O9)),"E_INVALID_DATE",IF(O9<>INT(O9),"E_INVALID_DATE",""))),IF(N9="MONTH",IF(OR(R9="",S9=""),"E_MISSING_INPUT",IF(OR(NOT(ISNUMBER(R9)),NOT(ISNUMBER(S9))),"E_INVALID_DATE",IF(OR(R9<1900,R9>9999,R9<>INT(R9),S9<1,S9>12,S9<>INT(S9)),"E_INVALID_DATE",""))),IF(N9="YEAR",IF(R9="","E_MISSING_INPUT",IF(NOT(ISNUMBER(R9)),"E_INVALID_DATE",IF(OR(R9<1900,R9>9999,R9<>INT(R9)),"E_INVALID_DATE",""))),IF(N9="RANGE",IF(OR(T9="",U9=""),"E_MISSING_INPUT",IF(OR(NOT(ISNUMBER(T9)),NOT(ISNUMBER(U9))),"E_INVALID_DATE",IF(OR(T9<>INT(T9),U9<>INT(U9)),"E_INVALID_DATE",IF(T9>U9,"E_REVERSED_BOUNDS","")))),"E_MISSING_INPUT"))))))) | X9: =IF(AND(W9="",N9="TIMESTAMP"),1,0) -> 0 | Y9: =IF(AND(X9=1,Q9<>"unknown"),1,0) -> 0 | Z9: =IF(OR(W9<>"",N9=""),"",IF(OR(N9="TIMESTAMP",N9="DATE"),O9,IF(N9="MONTH",DATE(R9,S9,1),IF(N9="YEAR",DATE(R9,1,1),T9)))) | AA9: =IF(OR(W9<>"",N9=""),"",IF(OR(N9="TIMESTAMP",N9="DATE"),O9,IF(N9="MONTH",EOMONTH(DATE(R9,S9,1),0),IF(N9="YEAR",DATE(R9,12,31),U9)))) | AB9: =IF(X9=1,O9*1440+ROUND(P9*1440,0),"") | AC9: =IF(Y9=1,AB9-(IF(LEFT(Q9,1)="-",-1,1)*(VALUE(MID(Q9,2,2))*60+VALUE(MID(Q9,5,2)))),"") | AN9: =IF(COUNTA(AE9:AL9)=0,"",IF(AE9="","E_MISSING_INPUT",IF(AE9="TIMESTAMP",IF(OR(AF9="",AG9="",AH9=""),"E_MISSING_INPUT",IF(OR(NOT(ISNUMBER(AF9)),NOT(ISNUMBER(AG9))),"E_INVALID_DATE",IF(OR(AF9<>INT(AF9),AG9<0,AG9>=1),"E_INVALID_DATE",IF(ISNA(MATCH(AH9,nLIST_Offset,0)),"E_INVALID_DATE","")))),IF(AE9="DATE",IF(AF9="","E_MISSING_INPUT",IF(NOT(ISNUMBER(AF9)),"E_INVALID_DATE",IF(AF9<>INT(AF9),"E_INVALID_DATE",""))),IF(AE9="MONTH",IF(OR(AI9="",AJ9=""),"E_MISSING_INPUT",IF(OR(NOT(ISNUMBER(AI9)),NOT(ISNUMBER(AJ9))),"E_INVALID_DATE",IF(OR(AI9<1900,AI9>9999,AI9<>INT(AI9),AJ9<1,AJ9>12,AJ9<>INT(AJ9)),"E_INVALID_DATE",""))),IF(AE9="YEAR",IF(AI9="","E_MISSING_INPUT",IF(NOT(ISNUMBER(AI9)),"E_INVALID_DATE",IF(OR(AI9<1900,AI9>9999,AI9<>INT(AI9)),"E_INVALID_DATE",""))),IF(AE9="RANGE",IF(OR(AK9="",AL9=""),"E_MISSING_INPUT",IF(OR(NOT(ISNUMBER(AK9)),NOT(ISNUMBER(AL9))),"E_INVALID_DATE",IF(OR(AK9<>INT(AK9),AL9<>INT(AL9)),"E_INVALID_DATE",IF(AK9>AL9,"E_REVERSED_BOUNDS","")))),"E_MISSING_INPUT"))))))) | AO9: =IF(AND(AN9="",AE9="TIMESTAMP"),1,0) -> 0 | AP9: =IF(AND(AO9=1,AH9<>"unknown"),1,0) -> 0 | AQ9: =IF(OR(AN9<>"",AE9=""),"",IF(OR(AE9="TIMESTAMP",AE9="DATE"),AF9,IF(AE9="MONTH",DATE(AI9,AJ9,1),IF(AE9="YEAR",DATE(AI9,1,1),AK9)))) | AR9: =IF(OR(AN9<>"",AE9=""),"",IF(OR(AE9="TIMESTAMP",AE9="DATE"),AF9,IF(AE9="MONTH",EOMONTH(DATE(AI9,AJ9,1),0),IF(AE9="YEAR",DATE(AI9,12,31),AL9)))) | AS9: =IF(AO9=1,AF9*1440+ROUND(AG9*1440,0),"") | AT9: =IF(AP9=1,AS9-(IF(LEFT(AH9,1)="-",-1,1)*(VALUE(MID(AH9,2,2))*60+VALUE(MID(AH9,5,2)))),"") | BE9: =IF(COUNTA(AV9:BC9)=0,"",IF(AV9="","E_MISSING_INPUT",IF(AV9="TIMESTAMP",IF(OR(AW9="",AX9="",AY9=""),"E_MISSING_INPUT",IF(OR(NOT(ISNUMBER(AW9)),NOT(ISNUMBER(AX9))),"E_INVALID_DATE",IF(OR(AW9<>INT(AW9),AX9<0,AX9>=1),"E_INVALID_DATE",IF(ISNA(MATCH(AY9,nLIST_Offset,0)),"E_INVALID_DATE","")))),IF(AV9="DATE",IF(AW9="","E_MISSING_INPUT",IF(NOT(ISNUMBER(AW9)),"E_INVALID_DATE",IF(AW9<>INT(AW9),"E_INVALID_DATE",""))),IF(AV9="MONTH",IF(OR(AZ9="",BA9=""),"E_MISSING_INPUT",IF(OR(NOT(ISNUMBER(AZ9)),NOT(ISNUMBER(BA9))),"E_INVALID_DATE",IF(OR(AZ9<1900,AZ9>9999,AZ9<>INT(AZ9),BA9<1,BA9>12,BA9<>INT(BA9)),"E_INVALID_DATE",""))),IF(AV9="YEAR",IF(AZ9="","E_MISSING_INPUT",IF(NOT(ISNUMBER(AZ9)),"E_INVALID_DATE",IF(OR(AZ9<1900,AZ9>9999,AZ9<>INT(AZ9)),"E_INVALID_DATE",""))),IF(AV9="RANGE",IF(OR(BB9="",BC9=""),"E_MISSING_INPUT",IF(OR(NOT(ISNUMBER(BB9)),NOT(ISNUMBER(BC9))),"E_INVALID_DATE",IF(OR(BB9<>INT(BB9),BC9<>INT(BC9)),"E_INVALID_DATE",IF(BB9>BC9,"E_REVERSED_BOUNDS","")))),"E_MISSING_INPUT"))))))) | BF9: =IF(AND(BE9="",AV9="TIMESTAMP"),1,0) -> 0 | BG9: =IF(AND(BF9=1,AY9<>"unknown"),1,0) -> 0 | BH9: =IF(OR(BE9<>"",AV9=""),"",IF(OR(AV9="TIMESTAMP",AV9="DATE"),AW9,IF(AV9="MONTH",DATE(AZ9,BA9,1),IF(AV9="YEAR",DATE(AZ9,1,1),BB9)))) | BI9: =IF(OR(BE9<>"",AV9=""),"",IF(OR(AV9="TIMESTAMP",AV9="DATE"),AW9,IF(AV9="MONTH",EOMONTH(DATE(AZ9,BA9,1),0),IF(AV9="YEAR",DATE(AZ9,12,31),BC9)))) | BJ9: =IF(BF9=1,AW9*1440+ROUND(AX9*1440,0),"") | BK9: =IF(BG9=1,BJ9-(IF(LEFT(AY9,1)="-",-1,1)*(VALUE(MID(AY9,2,2))*60+VALUE(MID(AY9,5,2)))),"") | BL9: =IF(D9="","",A9&"|"&B9&"|"&D9) | BM9: =IF(BL9="",0,COUNTIF(nEXP_Key,BL9)) -> 0 | BN9: =IF(D9="",IF(COUNTA(C9,E9,N9,O9)>0,"E_MISSING_INPUT",""),IF(BM9>1,"E_DUPLICATE_ID",IF(W9<>"",W9,IF(AN9<>"",AN9,BE9)))) | BO9: =IF(BN9="","",BN9&": "&SUBSTITUTE(IFERROR(INDEX(nMSG_Text,MATCH(BN9,nMSG_Code,0)),""),"[input]",IF(D9="","an Exposure_Episode_ID","the date fields required by the selected precision")))
W10: =IF(COUNTA(N10:U10)=0,"",IF(N10="","E_MISSING_INPUT",IF(N10="TIMESTAMP",IF(OR(O10="",P10="",Q10=""),"E_MISSING_INPUT",IF(OR(NOT(ISNUMBER(O10)),NOT(ISNUMBER(P10))),"E_INVALID_DATE",IF(OR(O10<>INT(O10),P10<0,P10>=1),"E_INVALID_DATE",IF(ISNA(MATCH(Q10,nLIST_Offset,0)),"E_INVALID_DATE","")))),IF(N10="DATE",IF(O10="","E_MISSING_INPUT",IF(NOT(ISNUMBER(O10)),"E_INVALID_DATE",IF(O10<>INT(O10),"E_INVALID_DATE",""))),IF(N10="MONTH",IF(OR(R10="",S10=""),"E_MISSING_INPUT",IF(OR(NOT(ISNUMBER(R10)),NOT(ISNUMBER(S10))),"E_INVALID_DATE",IF(OR(R10<1900,R10>9999,R10<>INT(R10),S10<1,S10>12,S10<>INT(S10)),"E_INVALID_DATE",""))),IF(N10="YEAR",IF(R10="","E_MISSING_INPUT",IF(NOT(ISNUMBER(R10)),"E_INVALID_DATE",IF(OR(R10<1900,R10>9999,R10<>INT(R10)),"E_INVALID_DATE",""))),IF(N10="RANGE",IF(OR(T10="",U10=""),"E_MISSING_INPUT",IF(OR(NOT(ISNUMBER(T10)),NOT(ISNUMBER(U10))),"E_INVALID_DATE",IF(OR(T10<>INT(T10),U10<>INT(U10)),"E_INVALID_DATE",IF(T10>U10,"E_REVERSED_BOUNDS","")))),"E_MISSING_INPUT"))))))) | X10: =IF(AND(W10="",N10="TIMESTAMP"),1,0) -> 0 | Y10: =IF(AND(X10=1,Q10<>"unknown"),1,0) -> 0 | Z10: =IF(OR(W10<>"",N10=""),"",IF(OR(N10="TIMESTAMP",N10="DATE"),O10,IF(N10="MONTH",DATE(R10,S10,1),IF(N10="YEAR",DATE(R10,1,1),T10)))) | AA10: =IF(OR(W10<>"",N10=""),"",IF(OR(N10="TIMESTAMP",N10="DATE"),O10,IF(N10="MONTH",EOMONTH(DATE(R10,S10,1),0),IF(N10="YEAR",DATE(R10,12,31),U10)))) | AB10: =IF(X10=1,O10*1440+ROUND(P10*1440,0),"") | AC10: =IF(Y10=1,AB10-(IF(LEFT(Q10,1)="-",-1,1)*(VALUE(MID(Q10,2,2))*60+VALUE(MID(Q10,5,2)))),"") | AN10: =IF(COUNTA(AE10:AL10)=0,"",IF(AE10="","E_MISSING_INPUT",IF(AE10="TIMESTAMP",IF(OR(AF10="",AG10="",AH10=""),"E_MISSING_INPUT",IF(OR(NOT(ISNUMBER(AF10)),NOT(ISNUMBER(AG10))),"E_INVALID_DATE",IF(OR(AF10<>INT(AF10),AG10<0,AG10>=1),"E_INVALID_DATE",IF(ISNA(MATCH(AH10,nLIST_Offset,0)),"E_INVALID_DATE","")))),IF(AE10="DATE",IF(AF10="","E_MISSING_INPUT",IF(NOT(ISNUMBER(AF10)),"E_INVALID_DATE",IF(AF10<>INT(AF10),"E_INVALID_DATE",""))),IF(AE10="MONTH",IF(OR(AI10="",AJ10=""),"E_MISSING_INPUT",IF(OR(NOT(ISNUMBER(AI10)),NOT(ISNUMBER(AJ10))),"E_INVALID_DATE",IF(OR(AI10<1900,AI10>9999,AI10<>INT(AI10),AJ10<1,AJ10>12,AJ10<>INT(AJ10)),"E_INVALID_DATE",""))),IF(AE10="YEAR",IF(AI10="","E_MISSING_INPUT",IF(NOT(ISNUMBER(AI10)),"E_INVALID_DATE",IF(OR(AI10<1900,AI10>9999,AI10<>INT(AI10)),"E_INVALID_DATE",""))),IF(AE10="RANGE",IF(OR(AK10="",AL10=""),"E_MISSING_INPUT",IF(OR(NOT(ISNUMBER(AK10)),NOT(ISNUMBER(AL10))),"E_INVALID_DATE",IF(OR(AK10<>INT(AK10),AL10<>INT(AL10)),"E_INVALID_DATE",IF(AK10>AL10,"E_REVERSED_BOUNDS","")))),"E_MISSING_INPUT"))))))) | AO10: =IF(AND(AN10="",AE10="TIMESTAMP"),1,0) -> 0 | AP10: =IF(AND(AO10=1,AH10<>"unknown"),1,0) -> 0 | AQ10: =IF(OR(AN10<>"",AE10=""),"",IF(OR(AE10="TIMESTAMP",AE10="DATE"),AF10,IF(AE10="MONTH",DATE(AI10,AJ10,1),IF(AE10="YEAR",DATE(AI10,1,1),AK10)))) | AR10: =IF(OR(AN10<>"",AE10=""),"",IF(OR(AE10="TIMESTAMP",AE10="DATE"),AF10,IF(AE10="MONTH",EOMONTH(DATE(AI10,AJ10,1),0),IF(AE10="YEAR",DATE(AI10,12,31),AL10)))) | AS10: =IF(AO10=1,AF10*1440+ROUND(AG10*1440,0),"") | AT10: =IF(AP10=1,AS10-(IF(LEFT(AH10,1)="-",-1,1)*(VALUE(MID(AH10,2,2))*60+VALUE(MID(AH10,5,2)))),"") | BE10: =IF(COUNTA(AV10:BC10)=0,"",IF(AV10="","E_MISSING_INPUT",IF(AV10="TIMESTAMP",IF(OR(AW10="",AX10="",AY10=""),"E_MISSING_INPUT",IF(OR(NOT(ISNUMBER(AW10)),NOT(ISNUMBER(AX10))),"E_INVALID_DATE",IF(OR(AW10<>INT(AW10),AX10<0,AX10>=1),"E_INVALID_DATE",IF(ISNA(MATCH(AY10,nLIST_Offset,0)),"E_INVALID_DATE","")))),IF(AV10="DATE",IF(AW10="","E_MISSING_INPUT",IF(NOT(ISNUMBER(AW10)),"E_INVALID_DATE",IF(AW10<>INT(AW10),"E_INVALID_DATE",""))),IF(AV10="MONTH",IF(OR(AZ10="",BA10=""),"E_MISSING_INPUT",IF(OR(NOT(ISNUMBER(AZ10)),NOT(ISNUMBER(BA10))),"E_INVALID_DATE",IF(OR(AZ10<1900,AZ10>9999,AZ10<>INT(AZ10),BA10<1,BA10>12,BA10<>INT(BA10)),"E_INVALID_DATE",""))),IF(AV10="YEAR",IF(AZ10="","E_MISSING_INPUT",IF(NOT(ISNUMBER(AZ10)),"E_INVALID_DATE",IF(OR(AZ10<1900,AZ10>9999,AZ10<>INT(AZ10)),"E_INVALID_DATE",""))),IF(AV10="RANGE",IF(OR(BB10="",BC10=""),"E_MISSING_INPUT",IF(OR(NOT(ISNUMBER(BB10)),NOT(ISNUMBER(BC10))),"E_INVALID_DATE",IF(OR(BB10<>INT(BB10),BC10<>INT(BC10)),"E_INVALID_DATE",IF(BB10>BC10,"E_REVERSED_BOUNDS","")))),"E_MISSING_INPUT"))))))) | BF10: =IF(AND(BE10="",AV10="TIMESTAMP"),1,0) -> 0 | BG10: =IF(AND(BF10=1,AY10<>"unknown"),1,0) -> 0 | BH10: =IF(OR(BE10<>"",AV10=""),"",IF(OR(AV10="TIMESTAMP",AV10="DATE"),AW10,IF(AV10="MONTH",DATE(AZ10,BA10,1),IF(AV10="YEAR",DATE(AZ10,1,1),BB10)))) | BI10: =IF(OR(BE10<>"",AV10=""),"",IF(OR(AV10="TIMESTAMP",AV10="DATE"),AW10,IF(AV10="MONTH",EOMONTH(DATE(AZ10,BA10,1),0),IF(AV10="YEAR",DATE(AZ10,12,31),BC10)))) | BJ10: =IF(BF10=1,AW10*1440+ROUND(AX10*1440,0),"") | BK10: =IF(BG10=1,BJ10-(IF(LEFT(AY10,1)="-",-1,1)*(VALUE(MID(AY10,2,2))*60+VALUE(MID(AY10,5,2)))),"") | BL10: =IF(D10="","",A10&"|"&B10&"|"&D10) | BM10: =IF(BL10="",0,COUNTIF(nEXP_Key,BL10)) -> 0 | BN10: =IF(D10="",IF(COUNTA(C10,E10,N10,O10)>0,"E_MISSING_INPUT",""),IF(BM10>1,"E_DUPLICATE_ID",IF(W10<>"",W10,IF(AN10<>"",AN10,BE10)))) | BO10: =IF(BN10="","",BN10&": "&SUBSTITUTE(IFERROR(INDEX(nMSG_Text,MATCH(BN10,nMSG_Code,0)),""),"[input]",IF(D10="","an Exposure_Episode_ID","the date fields required by the selected precision")))
